I'm sorry, but an uncaught exception occurred.

While running game code:
Exception: Line with id escena1RN_cabfb097 appeared twice, at game/acto1/escena1RN.rpy:2 and game/acto1/escena1RN.rpy:2.

-- Full Traceback ------------------------------------------------------------

Full traceback:
  File "C:\Users\verge\Documents\renpy-8.0.3-sdk\renpy\bootstrap.py", line 277, in bootstrap
    renpy.main.main()
  File "C:\Users\verge\Documents\renpy-8.0.3-sdk\renpy\main.py", line 490, in main
    renpy.game.script.load_script() # sets renpy.game.script.
  File "C:\Users\verge\Documents\renpy-8.0.3-sdk\renpy\script.py", line 297, in load_script
    self.load_appropriate_file(".rpyc", ".rpy", dir, fn, initcode)
  File "C:\Users\verge\Documents\renpy-8.0.3-sdk\renpy\script.py", line 809, in load_appropriate_file
    self.finish_load(stmts, initcode, filename=lastfn) # type: ignore
  File "C:\Users\verge\Documents\renpy-8.0.3-sdk\renpy\script.py", line 427, in finish_load
    self.translator.take_translates(all_stmts)
  File "C:\Users\verge\Documents\renpy-8.0.3-sdk\renpy\translation\__init__.py", line 166, in take_translates
    raise Exception("Line with id %s appeared twice, at %s:%d and %s:%d." %
Exception: Line with id escena1RN_cabfb097 appeared twice, at game/acto1/escena1RN.rpy:2 and game/acto1/escena1RN.rpy:2.

Windows-10-10.0.22621 AMD64
Ren'Py 8.0.3.22090809
 
Tue May 23 21:45:43 2023
